Workbook
Name Slicer_State: #N/A
Name Timeline_Year: #N/A

Sheet Dashboard
S1: State | T1: DELAWARE

Sheet finance
A1: State | B1: Year1 | C1: Year | D1: Capital_Outlay | E1: Total_Revenue | F1: Total_Expenditure | G1: General_Expenditure | H1: General_Revenue | I1: Insurance_Trust_Revenue | J1: Intergovernmental_Revenue | K1: License_Tax | L1: Selective_Sales_Tax | M1: Total_Tax | N1: Correction_Total | O1: Education_Total | P1: Financial_Aid_Subsidies | Q1: Financial_Aid_Cash_Securities | R1: Health_Expenditure | S1: Intergov_Expenditure | T1: Intergov_Unallocable | U1: Natural_Resources_Construction | V1: Utilities_Current_Operation | W1: Welfare_Expenditure | X1: Parks_Expenditure | Y1: Highways_Expenditure | Z1: Debt_End_Fiscal_Year | AA1: Insurance_Benefits_Repayments | AB1: Interest_on_Debt | AC1: Interest_on_General_Debt | AD1: Misc_General_Revenue | AE1: Other_Taxes | AF1: Police_Protection
A2: ALABAMA | B2: 1992 | C2: =DATE(finance[[#This Row],[Year1]],1,1) -> 33604 | D2: 664748 | E2: 10536166 | F2: 9650515 | G2: 8788293 | H2: 8910315 | I2: 1473217 | J2: 2737180 | K2: 395202 | L2: 1103368 | M2: 4217916 | N2: 182698 | O2: 3570524 | P2: 273050 | Q2: 14594322 | R2: 394119 | S2: 2143312 | T2: 518611 | U2: 151432 | V2: 5564374 | W2: 1853436 | X2: 9728 | Y2: 694874 | Z2: 4128724 | AA2: 724852 | AB2: 280179 | AC2: 280179 | AD2: 607453 | AE2: 205227 | AF2: 77789
A3: ALABAMA | B3: 1993 | C3: =DATE(finance[[#This Row],[Year1]],1,1) -> 33970 | D3: 781952 | E3: 11389335 | F3: 10242374 | G3: 9339796 | H3: 9688246 | I3: 1570768 | J3: 2965310 | K3: 377723 | L3: 1324610 | M3: 4639784 | N3: 182217 | O3: 3663465 | P3: 306485 | Q3: 15506309 | R3: 412456 | S3: 2211563 | T3: 527474 | U3: 156698 | V3: 5913144 | W3: 2016935 | X3: 11031 | Y3: 856228 | Z3: 4170084 | AA3: 761582 | AB3: 267648 | AC3: 267648 | AD3: 599988 | AE3: 224878 | AF3: 78320
A4: ALABAMA | B4: 1994 | C4: =DATE(finance[[#This Row],[Year1]],1,1) -> 34335 | D4: 767100 | E4: 11599362 | F4: 10815221 | G4: 9922352 | H4: 10014415 | I4: 1454982 | J4: 3077084 | K4: 386771 | L4: 1280747 | M4: 4767108 | N4: 216691 | O4: 3969277 | P4: 315344 | Q4: 16206051 | R4: 487044 | S4: 2349153 | T4: 563733 | U4: 169019 | V4: 6370171 | W4: 2167799 | X4: 12053 | Y4: 883852 | Z4: 3853804 | AA4: 762811 | AB4: 250642 | AC4: 250642 | AD4: 643807 | AE4: 234592 | AF4: 86839
A5: ALABAMA | B5: 1995 | C5: =DATE(finance[[#This Row],[Year1]],1,1) -> 34700 | D5: 808001 | E5: 12279726 | F5: 11541881 | G5: 10489513 | H5: 10582838 | I5: 1566923 | J5: 3240417 | K5: 480698 | L5: 1280494 | M5: 5077827 | N5: 231357 | O5: 4400912 | P5: 303811 | Q5: 17373025 | R5: 491648 | S5: 2619713 | T5: 565505 | U5: 185903 | V5: 6703955 | W5: 2291264 | X5: 10645 | Y5: 924411 | Z5: 3758726 | AA5: 912649 | AB5: 193752 | AC5: 193752 | AD5: 643469 | AE5: 232783 | AF5: 83482
A6: ALABAMA | B6: 1996 | C6: =DATE(finance[[#This Row],[Year1]],1,1) -> 35065 | D6: 760751 | E6: 12741148 | F6: 12126587 | G6: 10991713 | H6: 10894396 | I6: 1710360 | J6: 3347019 | K6: 422841 | L6: 1334829 | M6: 5257771 | N6: 220046 | O6: 4872259 | P6: 301698 | Q6: 18013799 | R6: 514380 | S6: 3076820 | T6: 587074 | U6: 173797 | V6: 6782766 | W6: 2325418 | X6: 7788 | Y6: 881381 | Z6: 3645292 | AA6: 987710 | AB6: 216842 | AC6: 216842 | AD6: 649073 | AE6: 265426 | AF6: 86936
A7: ALABAMA | B7: 1997 | C7: =DATE(finance[[#This Row],[Year1]],1,1) -> 35431 | D7: 770809 | E7: 14007883 | F7: 12944867 | G7: 11668841 | H7: 11487011 | I7: 2381696 | J7: 3553541 | K7: 424165 | L7: 1360764 | M7: 5484161 | N7: 233870 | O7: 5175279 | P7: 282494 | Q7: 21639230 | R7: 566651 | S7: 3292491 | T7: 625765 | U7: 175948 | V7: 7241270 | W7: 2537627 | X7: 16320 | Y7: 837255 | Z7: 3780493 | AA7: 1134137 | AB7: 223666 | AC7: 223666 | AD7: 669731 | AE7: 279304 | AF7: 93163
A8: ALABAMA | B8: 1998 | C8: =DATE(finance[[#This Row],[Year1]],1,1) -> 35796 | D8: 755486 | E8: 14843951 | F8: 13728431 | G8: 12475614 | H8: 12433410 | I8: 2268663 | J8: 4021037 | K8: 434433 | L8: 1422930 | M8: 5739128 | N8: 257214 | O8: 5362196 | P8: 668076 | Q8: 23466316 | R8: 554980 | S8: 3419845 | T8: 620254 | U8: 180408 | V8: 7575449 | W8: 3027120 | X8: 20222 | Y8: 882080 | Z8: 4166572 | AA8: 1107068 | AB8: 202507 | AC8: 202507 | AD8: 778771 | AE8: 268751 | AF8: 102178
A9: ALABAMA | B9: 1999 | C9: =DATE(finance[[#This Row],[Year1]],1,1) -> 36161 | D9: 851302 | E9: 15501093 | F9: 14701938 | G9: 13289087 | H9: 13093255 | I9: 2262606 | J9: 4281715 | K9: 454177 | L9: 1480248 | M9: 6032234 | N9: 282458 | O9: 5751997 | P9: 682036 | Q9: 24768728 | R9: 588248 | S9: 3631426 | T9: 655661 | U9: 202937 | V9: 8068008 | W9: 3195049 | X9: 15401 | Y9: 921658 | Z9: 4467074 | AA9: 1271203 | AB9: 197963 | AC9: 197963 | AD9: 793813 | AE9: 308206 | AF9: 113709
A10: ALABAMA | B10: 2000 | C10: =DATE(finance[[#This Row],[Year1]],1,1) -> 36526 | D10: 1136551 | E10: 16856646 | F10: 15872589 | G10: 14399604 | H10: 14116821 | I10: 2588130 | J10: 4781099 | K10: 541645 | L10: 1526560 | M10: 6438438 | N10: 278856 | O10: 6224938 | P10: 726205 | Q10: 25953796 | R10: 598894 | S10: 3908350 | T10: 770460 | U10: 194417 | V10: 8503158 | W10: 3484564 | X10: 11326 | Y10: 1076311 | Z10: 5291796 | AA10: 1322395 | AB10: 275930 | AC10: 275930 | AD10: 797887 | AE10: 353816 | AF10: 117831
A11: ALABAMA | B11: 2001 | C11: =DATE(finance[[#This Row],[Year1]],1,1) -> 36892 | D11: 1214496 | E11: 17859899 | F11: 16718151 | G11: 15055914 | H11: 15731646 | I11: 1972924 | J11: 5715592 | K11: 432671 | L11: 1585107 | M11: 6747707 | N11: 303759 | O11: 6385451 | P11: 783882 | Q11: 28094479 | R11: 644288 | S11: 3892653 | T11: 712374 | U11: 205794 | V11: 9053735 | W11: 3776253 | X11: 15956 | Y11: 1163889 | Z11: 5577158 | AA11: 1505848 | AB11: 267537 | AC11: 267537 | AD11: 1052701 | AE11: 378117 | AF11: 124884
A12: ALABAMA | B12: 2002 | C12: =DATE(finance[[#This Row],[Year1]],1,1) -> 37257 | D12: 1445150 | E12: 14942192 | F12: 17996418 | G12: 16160326 | H12: 15986065 | I12: -1204495 | J12: 6275399 | K12: 394973 | L12: 1634833 | M12: 6509765 | N12: 331476 | O12: 6811434 | P12: 929215 | Q12: 25872581 | R12: 718443 | S12: 4095562 | T12: 775302 | U12: 230519 | V12: 9609567 | W12: 4110058 | X12: 23155 | Y12: 1255800 | Z12: 6405164 | AA12: 1675057 | AB12: 241867 | AC12: 241867 | AD12: 914681 | AE12: 378394 | AF12: 128801
A13: ALABAMA | B13: 2003 | C13: =DATE(finance[[#This Row],[Year1]],1,1) -> 37622 | D13: 1473974 | E13: 19098788 | F13: 18471110 | G13: 17009944 | H13: 16574756 | I13: 2356008 | J13: 6668784 | K13: 399871 | L13: 1585666 | M13: 6416351 | N13: 356928 | O13: 7053792 | P13: 1002597 | Q13: 28661435 | R13: 762009 | S13: 4074005 | T13: 858560 | U13: 225308 | V13: 10379978 | W13: 4531802 | X13: 25422 | Y13: 1163904 | Z13: 6284640 | AA13: 1288155 | AB13: 252401 | AC13: 252401 | AD13: 1018207 | AE13: 388308 | AF13: 129591
... A1051: WYOMING | B1051: 2019 | C1051: =DATE(finance[[#This Row],[Year1]],1,1) -> 43466 | D1051: 518769 | E1051: 6131182 | F1051: 6159829 | G1051: 5225356 | H1051: 5525161 | I1051: 484060 | J1051: 2291076 | K1051: 208741 | L1051: 183664 | M1051: 2110704 | N1051: 141336 | O1051: 1955128 | P1051: 44117 | Q1051: 33360328 | R1051: 296702 | S1051: 1320477 | T1051: 652099 | U1051: 222981 | V1051: 3423325 | W1051: 858064 | X1051: 22211 | Y1051: 494362 | Z1051: 882830 | AA1051: 826814 | AB1051: 26327 | AC1051: 26327 | AD1051: 873830 | AE1051: 948058 | AF1051: 41029

Sheet KPI
A3: Row Labels | B3: Sum of Total_Revenue | M3: State | N3: DELAWARE
A4: DELAWARE | B4: 128953153
A5: Grand Total | B5: 128953153 | C5: =GETPIVOTDATA("[Measures].[Sum of Total_Revenue]",$A$3) -> 128953153
W8: Row Labels | X8: Sum of Total_Expenditure
W9: DELAWARE | X9: 122270379
W10: Grand Total | X10: 122270379 | Y10: =GETPIVOTDATA("[Measures].[Sum of Total_Expenditure]",$W$8) -> 122270379
J59: Row Labels | K59: Sum of Debt_End_Fiscal_Year | L59: Sum of Total_Revenue | P59: Row Labels | Q59: Sum of Total_Revenue | R59: Sum of Total_Expenditure | S59: Surplus/Deficit
F60: Row Labels | G60: Sum of Debt_End_Fiscal_Year | J60: DELAWARE | K60: 90655817 | L60: 128953153 | P60: DELAWARE | Q60: 128953153 | R60: 122270379 | S60: =GETPIVOTDATA("[Measures].[Sum of Total_Revenue]",$P$59)-GETPIVOTDATA("[Measures].[Sum of Total_Expenditure]",$P$59) -> 6682774
F61: DELAWARE | G61: 90655817 | J61: Grand Total | K61: 90655817 | L61: 128953153 | M61: =GETPIVOTDATA("[Measures].[Sum of Debt_End_Fiscal_Year]",$J$59)/GETPIVOTDATA("[Measures].[Sum of Total_Revenue]",$J$59) -> 0.70301357 | P61: Grand Total | Q61: 128953153 | R61: 122270379
F62: Grand Total | G62: 90655817 | H62: =GETPIVOTDATA("[Measures].[Sum of Debt_End_Fiscal_Year]",$F$60) -> 90655817

Sheet Charts
B3: Row Labels | C3: Total Revenue | D3: Total Expenditure | I3: Row Labels | J3: Debt to revenue | S3: General | T3: Health | U3: Intergov | V3: Natural Resources | W3: Utilities | X3: Welfare | Y3: Parks | Z3: Highways | AA3: Police Protection | AB3: Correction | AC3: Education | AD3: Financial aid | AE3: Financial aid cash | AF3: Intergov unallocable | AG3: Insurance benefits
B4: DELAWARE | C4: 128953153 | D4: 122270379 | I4: DELAWARE | J4: 0.70301357 | R4: DELAWARE | S4: 111103044 | T4: 5924625 | U4: 20310129 | V4: 1322949 | W4: 73766893 | X4: 25443226 | Y4: 903922 | Z4: 7753079 | AA4: 1859787 | AB4: 4570827 | AC4: 39846288 | AD4: 3429634 | AE4: 218166309 | AF4: 8894622 | AG4: 9291646
B5: 1992 | C5: 2825218 | D5: 2474886 | I5: 1992 | J5: 1.2536802 | R5: Grand Total | S5: 111103044 | T5: 5924625 | U5: 20310129 | V5: 1322949 | W5: 73766893 | X5: 25443226 | Y5: 903922 | Z5: 7753079 | AA5: 1859787 | AB5: 4570827 | AC5: 39846288 | AD5: 3429634 | AE5: 218166309 | AF5: 8894622 | AG5: 9291646
B6: 1993 | C6: 2876324 | D6: 2556970 | I6: 1993 | J6: 1.2134906
B7: 1994 | C7: 3236782 | D7: 2617153 | I7: 1994 | J7: 1.0496459
B8: 1995 | C8: 3441210 | D8: 2980188 | I8: 1995 | J8: 1.0242022
B9: 1996 | C9: 3614209 | D9: 3248174 | I9: 1996 | J9: 1.1838106
B10: 1997 | C10: 4210673 | D10: 3403619 | I10: 1997 | J10: 0.81559314
B11: 1998 | C11: 4593997 | D11: 3465428 | I11: 1998 | J11: 0.82069253
B12: 1999 | C12: 4540445 | D12: 3940802 | I12: 1999 | J12: 0.81767822
B13: 2000 | C13: 5161880 | D13: 4210656 | I13: 2000 | J13: 0.6317549
B14: 2001 | C14: 5114008 | D14: 4311551 | I14: 2001 | J14: 0.76037562
B15: 2002 | C15: 4682495 | D15: 4644236 | I15: 2002 | J15: 0.86245794
B16: 2003 | C16: 5040703 | D16: 4857901 | I16: 2003 | J16: 0.86461769
B17: 2004 | C17: 5722682 | D17: 5387960 | I17: 2004 | J17: 0.73480267
... B21: 2015 | C21: 8169909 | D21: 8854841 | I21: 2015 | J21: 0.6077075
B22: 2016 | C22: 8172248 | D22: 9281102 | I22: 2016 | J22: 0.6173529 | M22: Row Labels | N22: Sum of Total_Revenue | O22: Sum of Total_Expenditure
B23: 2017 | C23: 9893929 | D23: 9993666 | I23: 2017 | J23: 0.51080375 | M23: DELAWARE | N23: 128953153 | O23: 122270379
B24: 2018 | C24: 10721781 | D24: 10070970 | I24: 2018 | J24: 0.47462077 | M24: 1992 | N24: 2825218 | O24: 2474886
B25: 2019 | C25: 10745653 | D25: 10569602 | I25: 2019 | J25: 0.46195378 | M25: 1993 | N25: 2876324 | O25: 2556970
B26: Grand Total | C26: 128953153 | D26: 122270379 | I26: Grand Total | J26: 0.70301357 | M26: 1994 | N26: 3236782 | O26: 2617153
M27: 1995 | N27: 3441210 | O27: 2980188
M28: 1996 | N28: 3614209 | O28: 3248174
M29: 1997 | N29: 4210673 | O29: 3403619
M30: 1998 | N30: 4593997 | O30: 3465428
F31: 1992 | G31: =AVERAGEIFS(finance[Total_Revenue],finance[Year1],Charts!F31) -> 14870432 | H31: =AVERAGEIFS(finance[Total_Expenditure],finance[Year1],Charts!F31) -> 14032018 | M31: 1999 | N31: 4540445 | O31: 3940802
F32: 1993 | G32: =AVERAGEIFS(finance[Total_Revenue],finance[Year1],Charts!F32) -> 16117452 | H32: =AVERAGEIFS(finance[Total_Expenditure],finance[Year1],Charts!F32) -> 14864888 | M32: 2000 | N32: 5161880 | O32: 4210656
F33: 1994 | G33: =AVERAGEIFS(finance[Total_Revenue],finance[Year1],Charts!F33) -> 16917747 | H33: =AVERAGEIFS(finance[Total_Expenditure],finance[Year1],Charts!F33) -> 15589183 | M33: 2001 | N33: 5114008 | O33: 4311551
F34: 1995 | G34: =AVERAGEIFS(finance[Total_Revenue],finance[Year1],Charts!F34) -> 18075110 | H34: =AVERAGEIFS(finance[Total_Expenditure],finance[Year1],Charts!F34) -> 16737873 | M34: 2002 | N34: 4682495 | O34: 4644236
F35: 1996 | G35: =AVERAGEIFS(finance[Total_Revenue],finance[Year1],Charts!F35) -> 19334472 | H35: =AVERAGEIFS(finance[Total_Expenditure],finance[Year1],Charts!F35) -> 17191983 | M35: 2003 | N35: 5040703 | O35: 4857901
F36: 1997 | G36: =AVERAGEIFS(finance[Total_Revenue],finance[Year1],Charts!F36) -> 20788808 | H36: =AVERAGEIFS(finance[Total_Expenditure],finance[Year1],Charts!F36) -> 17867859 | M36: 2004 | N36: 5722682 | O36: 5387960
F37: 1998 | G37: =AVERAGEIFS(finance[Total_Revenue],finance[Year1],Charts!F37) -> 21917238 | H37: =AVERAGEIFS(finance[Total_Expenditure],finance[Year1],Charts!F37) -> 18600731 | M37: 2012 | N37: 7976118 | O37: 8035406
F38: 1999 | G38: =AVERAGEIFS(finance[Total_Revenue],finance[Year1],Charts!F38) -> 23057395 | H38: =AVERAGEIFS(finance[Total_Expenditure],finance[Year1],Charts!F38) -> 19967302 | M38: 2013 | N38: 9021776 | O38: 8538142
F39: 2000 | G39: =AVERAGEIFS(finance[Total_Revenue],finance[Year1],Charts!F39) -> 25216585 | H39: =AVERAGEIFS(finance[Total_Expenditure],finance[Year1],Charts!F39) -> 21681943 | M39: 2014 | N39: 9191113 | O39: 8827126
F40: 2001 | G40: =AVERAGEIFS(finance[Total_Revenue],finance[Year1],Charts!F40) -> 23608426 | H40: =AVERAGEIFS(finance[Total_Expenditure],finance[Year1],Charts!F40) -> 23705205 | M40: 2015 | N40: 8169909 | O40: 8854841
F41: 2002 | G41: =AVERAGEIFS(finance[Total_Revenue],finance[Year1],Charts!F41) -> 21940906 | H41: =AVERAGEIFS(finance[Total_Expenditure],finance[Year1],Charts!F41) -> 25657044 | M41: 2016 | N41: 8172248 | O41: 9281102
F42: 2003 | G42: =AVERAGEIFS(finance[Total_Revenue],finance[Year1],Charts!F42) -> 25913176 | H42: =AVERAGEIFS(finance[Total_Expenditure],finance[Year1],Charts!F42) -> 27180968 | M42: 2017 | N42: 9893929 | O42: 9993666
... F45: 2013 | G45: =AVERAGEIFS(finance[Total_Revenue],finance[Year1],Charts!F45) -> 44452918 | H45: =AVERAGEIFS(finance[Total_Expenditure],finance[Year1],Charts!F45) -> 40467153 | M45: Grand Total | N45: 128953153 | O45: 122270379
F46: 2014 | G46: =AVERAGEIFS(finance[Total_Revenue],finance[Year1],Charts!F46) -> 47148111 | H46: =AVERAGEIFS(finance[Total_Expenditure],finance[Year1],Charts!F46) -> 41572876
F47: 2015 | G47: =AVERAGEIFS(finance[Total_Revenue],finance[Year1],Charts!F47) -> 43295675 | H47: =AVERAGEIFS(finance[Total_Expenditure],finance[Year1],Charts!F47) -> 43232394
...

Sheet Map
B2: Row Labels | C2: Sum of Total_Revenue | E2: States | F2: All time revenue
B3: ALABAMA | C3: 444991929 | E3: ALABAMA | F3: 444991929
B4: ALASKA | C4: 187777011 | E4: ALASKA | F4: 187777011
B5: ARIZONA | C5: 520209538 | E5: ARIZONA | F5: 520209538
B6: ARKANSAS | C6: 305063847 | E6: ARKANSAS | F6: 305063847
B7: CALIFORNIA | C7: 4734767338 | E7: CALIFORNIA | F7: 4734767338
B8: COLORADO | C8: 448457709 | E8: COLORADO | F8: 448457709
B9: CONNECTICUT | C9: 462288926 | E9: CONNECTICUT | F9: 462288926
B10: DELAWARE | C10: 128953153 | E10: DELAWARE | F10: 128953153
B11: FLORIDA | C11: 1376954078 | E11: FLORIDA | F11: 1376954078
B12: GEORGIA | C12: 722398135 | E12: GEORGIA | F12: 722398135
B13: HAWAII | C13: 198125107 | E13: HAWAII | F13: 198125107
B14: IDAHO | C14: 143148780 | E14: IDAHO | F14: 143148780
... B52: WYOMING | C52: 98108436 | E52: WYOMING | F52: 98108436
B53: Grand Total | C53: 32688849977

Sheet Fin health
B2: Row Labels | C2: Sum of Debt_End_Fiscal_Year | D2: Measure 1 | E2: Debt to revenue
B3: ALABAMA | C3: 135145296 | D3: 4275866 | E3: 0.3037028
B4: ALASKA | C4: 103577659 | D4: 6897325 | E4: 0.55159925
B5: ARIZONA | C5: 160071410 | D5: 44489083 | E5: 0.30770564
B6: ARKANSAS | C6: 77586538 | D6: 20400938 | E6: 0.25432885
B7: CALIFORNIA | C7: 1968941160 | D7: 306269226 | E7: 0.4158475
B8: COLORADO | C8: 199364862 | D8: 21306968 | E8: 0.44455666
B9: CONNECTICUT | C9: 521669448 | D9: 31837362 | E9: 1.1284489
B10: DELAWARE | C10: 90655817 | D10: 6682774 | E10: 0.70301357
B11: FLORIDA | C11: 489775176 | D11: 129309579 | E11: 0.35569463
B12: GEORGIA | C12: 191312985 | D12: 38053309 | E12: 0.2648304
B13: HAWAII | C13: 142246756 | D13: 14343766 | E13: 0.71796431 | L13: Row Labels | M13: Debt to revenue
B14: IDAHO | C14: 52909745 | D14: 15597472 | E14: 0.36961366 | L14: ALABAMA | M14: 0.3037028
B15: ILLINOIS | C15: 886718999 | D15: 38791686 | E15: 0.7273585 | L15: ALASKA | M15: 0.55159925
B16: INDIANA | C16: 276803115 | D16: 23331333 | E16: 0.48332081 | L16: ARIZONA | M16: 0.30770564
B17: IOWA | C17: 84129344 | D17: 39506074 | E17: 0.24034263 | L17: TENNESSEE | M17: 0.19027545
B18: KANSAS | C18: 79924814 | D18: 11448502 | E18: 0.30068169 | L18: CALIFORNIA | M18: 0.4158475
B19: KENTUCKY | C19: 211380110 | D19: 5647185 | E19: 0.4650263 | L19: COLORADO | M19: 0.44455666
B20: LOUISIANA | C20: 256034751 | D20: 16008154 | E20: 0.53580578 | L20: MASSACHUSETTS | M20: 1.2438805
B21: MAINE | C21: 87553794 | D21: 11805331 | E21: 0.58479712 | L21: CONNECTICUT | M21: 1.1284489
B22: MARYLAND | C22: 358287830 | D22: 25816183 | E22: 0.58837934 | L22: FLORIDA | M22: 0.35569463
B23: MASSACHUSETTS | C23: 1061854393 | D23: -5064916 | E23: 1.2438805 | L23: WYOMING | M23: 0.20597982
B24: MICHIGAN | C24: 467524007 | D24: 52750898 | E24: 0.41888471 | L24: NEW HAMPSHIRE | M24: 1.1236903
B25: MINNESOTA | C25: 194115291 | D25: 62363241 | E25: 0.28303195 | L25: IDAHO | M25: 0.36961366
... B53: Grand Total | C53: 16008721128 | D53: 1915661661 | E53: 0.48973033 | L53: SOUTH CAROLINA | M53: 0.46456181
L54: DELAWARE | M54: 0.70301357
L55: NORTH CAROLINA | M55: 0.27037192
L56: MINNESOTA | M56: 0.28303195
L57: UTAH | M57: 0.3745497
L58: VERMONT | M58: 0.60655453
L59: VIRGINIA | M59: 0.49736654
L60: WASHINGTON | M60: 0.51029185
L61: WEST VIRGINIA | M61: 0.50265607
L62: WISCONSIN | M62: 0.50203126
L63: TEXAS | M63: 0.28465964
L79: TENNESSEE | M79: 0.19027545
L80: WYOMING | M80: 0.20597982
... L88: TEXAS | M88: 0.28465964
